<mujoco model="NBEL">

    <compiler angle="radian" meshdir="meshes" balanceinertia="true" />
    
    <asset>
        <mesh file="Base.stl" />
        <mesh file="Shoulder.stl" />
        <mesh file="Link1.stl" />
        <mesh file="Link2.stl" />
        <mesh file="Link3.stl" />
        <mesh file="Link4.stl" />
        <mesh file="Gripper.stl" />
        <mesh file="N.stl" />
        <mesh file="B.stl" />
        <mesh file="E.stl" />
        <mesh file="L.stl" />
        
        <texture  name="floor_tile" file="meshes/floor_tile.png" width="3000" height="3000" type="2d"/>
        <material name="tile" texture="floor_tile" specular="0" shininess="0" reflectance="0" emission="1" />
        <material name="black" specular="1" shininess="1" reflectance="1" rgba="0.08 0.08 0.08 1" emission="1" />
        <material name="gray" specular="1" shininess="1" reflectance="1" rgba="0.1 0.1 0.1 1" emission="1" />
        <material name="white" specular="1" shininess="1" reflectance="1" rgba="1 1 1 1" emission="1" />

        <texture name="foam_blocks" file="meshes/foam_blocks.png" width="1994" height="1884" type="2d"/>
        <material name="foam" texture="foam_blocks" specular="0" shininess="0" reflectance="0" emission="1" />
    </asset>

    <contact>
        <exclude body1="base_link" body2="link1"/>
        <exclude body1="link1"     body2="link2"/>
        <exclude body1="target"    body2="link6"/>
        <exclude body1="target"    body2="EE"/>
        <exclude body1="EE"        body2="link6"/>
        <exclude body1="integrator_pos"    body2="link6"/>
    </contact>

    <worldbody>
        
        <camera fovy="45" pos="1 1 1" />
        
        <body name="target" pos="0 0 -0.15" mocap="true">
            <geom name="target" type="sphere" size="0.04" rgba="0 1 0 .5"/>
        </body>

        <body name="integrator_pos" pos="0 0 0" mocap="true">
            <geom name="integrator_pos" type="sphere" size="0.04" rgba="250, 190, 88, 1"/>
        </body>
        
        <body name="hand" pos="0 0 0" mocap="true"/>
        <geom name="floor_foam_block" pos="0 0 0" size="0.5 0.5 0.05" type="plane" rgba="1 0.83 0.61 1" material="foam"/>
        <geom type="box" size=".02 .04 .06" rgba="0 .9 0 .5" contype="2"/>
        <geom name="floor_grey_tile" pos="0 0 -0.001" size="0.7 0.7 0.05" type="plane" material="tile"/>

        <light pos="0 1 1" dir="0 -1 -1" diffuse="1 1 1"/>

        <body name="base_link" pos="0 0 0">
            <geom name="link0" type="mesh" mesh="Base" pos="0 0 0" material="black"/>
            <inertial pos="0 0 0" mass="1.226" diaginertia="0.25 0.25 0.25"/>
            
            <body name="link1" pos="0 0 0.067">
            <joint name='joint0' pos="0 0 0" axis="0 0 1" ref="1.5708"/>
            <geom name="link1" type="mesh" mesh="Shoulder" pos="0 0 0" material="black"/>
            <inertial pos="0 0 0" mass="0.798614" diaginertia="0.3 0.3 0.3"/>
            
                <body name="link2" pos="0 0.0005 0.045">
                    <joint name='joint1' pos="0 -0.0008 0.0058" axis="1 0 0"/>
                    <geom name="link2" type="mesh" mesh="Link1" pos="0 0 0" euler="1.5708 0 0" material="black"/>
                    <geom name="N" type="mesh" mesh="N" pos="0 0.005 0.24" euler="-1.5708 0 0" material="white"/>
                    <geom name="B" type="mesh" mesh="B" pos="0 0.010 0.0025"   euler="1.5708 0 0" material="white"/>
                    <geom name="E" type="mesh" mesh="E" pos="0 0.010 0.005"   euler="1.5708 0 0" material="white"/>
                    <geom name="L" type="mesh" mesh="L" pos="0 0.005 0.0075"   euler="1.5708 3.14 0" material="white"/>
                    <inertial pos="0 -0.0008 0.0058" mass="0.792592" euler="1.5708 0 0" diaginertia="0.3 0.3 0.3"/>
                    
                    <body name="link3" pos="0 -0.057 0.3055">
                    <inertial pos="0 -0.0038 0.00" mass="0.322228" euler="1.5708 0 1.5708" diaginertia="0.275 0.275 0.275"/>
                    <joint name='joint2' pos="0 -0.0038 0.00" axis="1 0 0" ref="1.5708"/>
                    <geom name="link3" type="mesh" mesh="Link2" pos="0 0 0" euler="1.5708 0 1.5708" material="black"/>
                    
                        <body name="link4" pos="0 -0.1995 0.0">
                        <inertial pos="0 -0.0038 0.00" mass="0.414823" euler="1.5708 0 1.5708" diaginertia="0.175 0.175 0.175"/>
                        <joint name='joint3' pos="0 -0.0038 0.00" axis="0 1 0" ref="-1.5708"/>
                        <geom name="link4" type="mesh" mesh="Link3" pos="0 0 0" euler="1.5708 0 1.5708" material="black"/>
                    
                            <body name="link5" pos="0 -0.104 -0.005">
                                <inertial pos="0.00 0.00 0.00475" mass="0.115395" euler="0 0 0" diaginertia="0.175 0.175 0.175"/>
                                <joint name='joint4' pos="0.00 0.00 0.00475" axis="1 0 0" ref="0"/>
                                <geom name="link5" type="mesh" mesh="Link4" pos="0 0 0" euler="0 0 0" material="black"/>
                                    
                                    <body name="link6" pos="0 0.0075 0.05525">
                                    <inertial pos="0 0 0" mass="0.1666" euler="-1.5708 0 0" diaginertia="0.025 0.025 0.025"/>
                                    <joint name='joint5' pos="0 0 0" axis="0 0 1" ref="0"/>
                                    <geom name="link6" type="mesh" mesh="Gripper" pos="0 0 0" euler="-1.5708 0 0" material="gray"/>
                                
                                    <body
                                        name="EE" pos="0 -0.0075 0.2" euler="1.5708 1.5708 1.5708">
                                        <geom name="EE" type="sphere" size="0.04" rgba="0 1 0 .75"/>
                                    </body>
                                </body>
                            </body>
                        </body>
                    </body>
                </body>
            </body>
        </body>

    </worldbody>

    <actuator>
        <motor name="joint0_motor" joint="joint0"/>
        <motor name="joint1_motor" joint="joint1"/>
        <motor name="joint2_motor" joint="joint2"/>
        <motor name="joint3_motor" joint="joint3"/>
        <motor name="joint4_motor" joint="joint4"/>
        <motor name="joint5_motor" joint="joint5"/>
    </actuator>

</mujoco>
